[2025-02-19T14:21:08.903+0000] {local_task_job_runner.py:123} INFO - ::group::Pre task execution logs
[2025-02-19T14:21:08.914+0000] {taskinstance.py:2614} INFO - Dependencies all met for dep_context=non-requeueable deps ti=<TaskInstance: pipeline.save_data manual__2025-02-19T14:21:02.540678+00:00 [queued]>
[2025-02-19T14:21:09.022+0000] {taskinstance.py:2614} INFO - Dependencies all met for dep_context=requeueable deps ti=<TaskInstance: pipeline.save_data manual__2025-02-19T14:21:02.540678+00:00 [queued]>
[2025-02-19T14:21:09.022+0000] {taskinstance.py:2867} INFO - Starting attempt 1 of 1
[2025-02-19T14:21:09.031+0000] {taskinstance.py:2890} INFO - Executing <Task(_PythonDecoratedOperator): save_data> on 2025-02-19 14:21:02.540678+00:00
[2025-02-19T14:21:09.036+0000] {warnings.py:112} WARNING - /home/***/.local/lib/python3.12/site-packages/***/task/task_runner/standard_task_runner.py:70: DeprecationWarning: This process (pid=244) is multi-threaded, use of fork() may lead to deadlocks in the child.
  pid = os.fork()

[2025-02-19T14:21:09.037+0000] {standard_task_runner.py:72} INFO - Started process 246 to run task
[2025-02-19T14:21:09.037+0000] {standard_task_runner.py:104} INFO - Running: ['***', 'tasks', 'run', 'pipeline', 'save_data', 'manual__2025-02-19T14:21:02.540678+00:00', '--job-id', '1046', '--raw', '--subdir', 'DAGS_FOLDER/pipeline.py', '--cfg-path', '/tmp/tmp3txj4c4t']
[2025-02-19T14:21:09.039+0000] {standard_task_runner.py:105} INFO - Job 1046: Subtask save_data
[2025-02-19T14:21:09.065+0000] {task_command.py:467} INFO - Running <TaskInstance: pipeline.save_data manual__2025-02-19T14:21:02.540678+00:00 [running]> on host 5f8091faf500
[2025-02-19T14:21:09.131+0000] {taskinstance.py:3134} INFO - Exporting env vars: AIRFLOW_CTX_DAG_OWNER='***' AIRFLOW_CTX_DAG_ID='pipeline' AIRFLOW_CTX_TASK_ID='save_data' AIRFLOW_CTX_EXECUTION_DATE='2025-02-19T14:21:02.540678+00:00' AIRFLOW_CTX_TRY_NUMBER='1' AIRFLOW_CTX_DAG_RUN_ID='manual__2025-02-19T14:21:02.540678+00:00'
[2025-02-19T14:21:09.132+0000] {logging_mixin.py:190} INFO - Task instance is in running state
[2025-02-19T14:21:09.132+0000] {logging_mixin.py:190} INFO -  Previous state of the Task instance: queued
[2025-02-19T14:21:09.132+0000] {logging_mixin.py:190} INFO - Current task name:save_data state:running start_date:2025-02-19 14:21:08.915179+00:00
[2025-02-19T14:21:09.132+0000] {logging_mixin.py:190} INFO - Dag name:pipeline and current dag run status:running
[2025-02-19T14:21:09.132+0000] {taskinstance.py:732} INFO - ::endgroup::
[2025-02-19T14:21:09.133+0000] {safe_data.py:25} INFO - Starting to save data with 10 records.
[2025-02-19T14:21:09.133+0000] {taskinstance.py:3313} ERROR - Task failed with exception
Traceback (most recent call last):
  File "/home/airflow/.local/lib/python3.12/site-packages/airflow/models/taskinstance.py", line 768, in _execute_task
    result = _execute_callable(context=context, **execute_callable_kwargs)
             ^^^^^^^^^^^^^^^^^^^^^^^^^^^^^^^^^^^^^^^^^^^^^^^^^^^^^^^^^^^^^
  File "/home/airflow/.local/lib/python3.12/site-packages/airflow/models/taskinstance.py", line 734, in _execute_callable
    return ExecutionCallableRunner(
           ^^^^^^^^^^^^^^^^^^^^^^^^
  File "/home/airflow/.local/lib/python3.12/site-packages/airflow/utils/operator_helpers.py", line 252, in run
    return self.func(*args, **kwargs)
           ^^^^^^^^^^^^^^^^^^^^^^^^^^
  File "/home/airflow/.local/lib/python3.12/site-packages/airflow/models/baseoperator.py", line 424, in wrapper
    return func(self, *args, **kwargs)
           ^^^^^^^^^^^^^^^^^^^^^^^^^^^
  File "/home/airflow/.local/lib/python3.12/site-packages/airflow/decorators/base.py", line 266, in execute
    return_value = super().execute(context)
                   ^^^^^^^^^^^^^^^^^^^^^^^^
  File "/home/airflow/.local/lib/python3.12/site-packages/airflow/models/baseoperator.py", line 424, in wrapper
    return func(self, *args, **kwargs)
           ^^^^^^^^^^^^^^^^^^^^^^^^^^^
  File "/home/airflow/.local/lib/python3.12/site-packages/airflow/operators/python.py", line 238, in execute
    return_value = self.execute_callable()
                   ^^^^^^^^^^^^^^^^^^^^^^^
  File "/home/airflow/.local/lib/python3.12/site-packages/airflow/operators/python.py", line 256, in execute_callable
    return runner.run(*self.op_args, **self.op_kwargs)
           ^^^^^^^^^^^^^^^^^^^^^^^^^^^^^^^^^^^^^^^^^^^
  File "/home/airflow/.local/lib/python3.12/site-packages/airflow/utils/operator_helpers.py", line 252, in run
    return self.func(*args, **kwargs)
           ^^^^^^^^^^^^^^^^^^^^^^^^^^
  File "/opt/airflow/dags/operators/safe_data.py", line 27, in save_data
    df.columns = ['comment']  # Добавляем заголвок к DataFrame
    ^^^^^^^^^^
  File "/home/airflow/.local/lib/python3.12/site-packages/pandas/core/generic.py", line 6313, in __setattr__
    return object.__setattr__(self, name, value)
           ^^^^^^^^^^^^^^^^^^^^^^^^^^^^^^^^^^^^^
  File "properties.pyx", line 69, in pandas._libs.properties.AxisProperty.__set__
  File "/home/airflow/.local/lib/python3.12/site-packages/pandas/core/generic.py", line 814, in _set_axis
    self._mgr.set_axis(axis, labels)
  File "/home/airflow/.local/lib/python3.12/site-packages/pandas/core/internals/managers.py", line 238, in set_axis
    self._validate_set_axis(axis, new_labels)
  File "/home/airflow/.local/lib/python3.12/site-packages/pandas/core/internals/base.py", line 98, in _validate_set_axis
    raise ValueError(
ValueError: Length mismatch: Expected axis has 2 elements, new values have 1 elements
[2025-02-19T14:21:09.140+0000] {logging_mixin.py:190} INFO - Task instance in failure state
[2025-02-19T14:21:09.141+0000] {logging_mixin.py:190} INFO - Task start:2025-02-19 14:21:08.915179+00:00 end:2025-02-19 14:21:09.140674+00:00 duration:0.225495
[2025-02-19T14:21:09.141+0000] {logging_mixin.py:190} INFO - Task:<Task(_PythonDecoratedOperator): save_data> dag:<DAG: pipeline> dagrun:<DagRun pipeline @ 2025-02-19 14:21:02.540678+00:00: manual__2025-02-19T14:21:02.540678+00:00, state:running, queued_at: 2025-02-19 14:21:02.554141+00:00. externally triggered: True>
[2025-02-19T14:21:09.141+0000] {logging_mixin.py:190} INFO - Failure caused by Length mismatch: Expected axis has 2 elements, new values have 1 elements
[2025-02-19T14:21:09.141+0000] {taskinstance.py:1226} INFO - Marking task as FAILED. dag_id=pipeline, task_id=save_data, run_id=manual__2025-02-19T14:21:02.540678+00:00, execution_date=20250219T142102, start_date=20250219T142108, end_date=20250219T142109
[2025-02-19T14:21:09.154+0000] {taskinstance.py:341} INFO - ::group::Post task execution logs
[2025-02-19T14:21:09.154+0000] {standard_task_runner.py:124} ERROR - Failed to execute job 1046 for task save_data (Length mismatch: Expected axis has 2 elements, new values have 1 elements; 246)
Traceback (most recent call last):
  File "/home/airflow/.local/lib/python3.12/site-packages/airflow/task/task_runner/standard_task_runner.py", line 117, in _start_by_fork
    ret = args.func(args, dag=self.dag)
          ^^^^^^^^^^^^^^^^^^^^^^^^^^^^^
  File "/home/airflow/.local/lib/python3.12/site-packages/airflow/cli/cli_config.py", line 49, in command
    return func(*args, **kwargs)
           ^^^^^^^^^^^^^^^^^^^^^
  File "/home/airflow/.local/lib/python3.12/site-packages/airflow/utils/cli.py", line 116, in wrapper
    return f(*args, **kwargs)
           ^^^^^^^^^^^^^^^^^^
  File "/home/airflow/.local/lib/python3.12/site-packages/airflow/cli/commands/task_command.py", line 483, in task_run
    task_return_code = _run_task_by_selected_method(args, _dag, ti)
                       ^^^^^^^^^^^^^^^^^^^^^^^^^^^^^^^^^^^^^^^^^^^^
  File "/home/airflow/.local/lib/python3.12/site-packages/airflow/cli/commands/task_command.py", line 256, in _run_task_by_selected_method
    return _run_raw_task(args, ti)
           ^^^^^^^^^^^^^^^^^^^^^^^
  File "/home/airflow/.local/lib/python3.12/site-packages/airflow/cli/commands/task_command.py", line 341, in _run_raw_task
    return ti._run_raw_task(
           ^^^^^^^^^^^^^^^^^
  File "/home/airflow/.local/lib/python3.12/site-packages/airflow/utils/session.py", line 97, in wrapper
    return func(*args, session=session, **kwargs)
           ^^^^^^^^^^^^^^^^^^^^^^^^^^^^^^^^^^^^^^
  File "/home/airflow/.local/lib/python3.12/site-packages/airflow/models/taskinstance.py", line 3006, in _run_raw_task
    return _run_raw_task(
           ^^^^^^^^^^^^^^
  File "/home/airflow/.local/lib/python3.12/site-packages/airflow/models/taskinstance.py", line 274, in _run_raw_task
    TaskInstance._execute_task_with_callbacks(
  File "/home/airflow/.local/lib/python3.12/site-packages/airflow/models/taskinstance.py", line 3161, in _execute_task_with_callbacks
    result = self._execute_task(context, task_orig)
             ^^^^^^^^^^^^^^^^^^^^^^^^^^^^^^^^^^^^^^
  File "/home/airflow/.local/lib/python3.12/site-packages/airflow/models/taskinstance.py", line 3185, in _execute_task
    return _execute_task(self, context, task_orig)
           ^^^^^^^^^^^^^^^^^^^^^^^^^^^^^^^^^^^^^^^
  File "/home/airflow/.local/lib/python3.12/site-packages/airflow/models/taskinstance.py", line 768, in _execute_task
    result = _execute_callable(context=context, **execute_callable_kwargs)
             ^^^^^^^^^^^^^^^^^^^^^^^^^^^^^^^^^^^^^^^^^^^^^^^^^^^^^^^^^^^^^
  File "/home/airflow/.local/lib/python3.12/site-packages/airflow/models/taskinstance.py", line 734, in _execute_callable
    return ExecutionCallableRunner(
           ^^^^^^^^^^^^^^^^^^^^^^^^
  File "/home/airflow/.local/lib/python3.12/site-packages/airflow/utils/operator_helpers.py", line 252, in run
    return self.func(*args, **kwargs)
           ^^^^^^^^^^^^^^^^^^^^^^^^^^
  File "/home/airflow/.local/lib/python3.12/site-packages/airflow/models/baseoperator.py", line 424, in wrapper
    return func(self, *args, **kwargs)
           ^^^^^^^^^^^^^^^^^^^^^^^^^^^
  File "/home/airflow/.local/lib/python3.12/site-packages/airflow/decorators/base.py", line 266, in execute
    return_value = super().execute(context)
                   ^^^^^^^^^^^^^^^^^^^^^^^^
  File "/home/airflow/.local/lib/python3.12/site-packages/airflow/models/baseoperator.py", line 424, in wrapper
    return func(self, *args, **kwargs)
           ^^^^^^^^^^^^^^^^^^^^^^^^^^^
  File "/home/airflow/.local/lib/python3.12/site-packages/airflow/operators/python.py", line 238, in execute
    return_value = self.execute_callable()
                   ^^^^^^^^^^^^^^^^^^^^^^^
  File "/home/airflow/.local/lib/python3.12/site-packages/airflow/operators/python.py", line 256, in execute_callable
    return runner.run(*self.op_args, **self.op_kwargs)
           ^^^^^^^^^^^^^^^^^^^^^^^^^^^^^^^^^^^^^^^^^^^
  File "/home/airflow/.local/lib/python3.12/site-packages/airflow/utils/operator_helpers.py", line 252, in run
    return self.func(*args, **kwargs)
           ^^^^^^^^^^^^^^^^^^^^^^^^^^
  File "/opt/airflow/dags/operators/safe_data.py", line 27, in save_data
    df.columns = ['comment']  # Добавляем заголвок к DataFrame
    ^^^^^^^^^^
  File "/home/airflow/.local/lib/python3.12/site-packages/pandas/core/generic.py", line 6313, in __setattr__
    return object.__setattr__(self, name, value)
           ^^^^^^^^^^^^^^^^^^^^^^^^^^^^^^^^^^^^^
  File "properties.pyx", line 69, in pandas._libs.properties.AxisProperty.__set__
  File "/home/airflow/.local/lib/python3.12/site-packages/pandas/core/generic.py", line 814, in _set_axis
    self._mgr.set_axis(axis, labels)
  File "/home/airflow/.local/lib/python3.12/site-packages/pandas/core/internals/managers.py", line 238, in set_axis
    self._validate_set_axis(axis, new_labels)
  File "/home/airflow/.local/lib/python3.12/site-packages/pandas/core/internals/base.py", line 98, in _validate_set_axis
    raise ValueError(
ValueError: Length mismatch: Expected axis has 2 elements, new values have 1 elements
[2025-02-19T14:21:09.179+0000] {local_task_job_runner.py:266} INFO - Task exited with return code 1
[2025-02-19T14:21:09.192+0000] {taskinstance.py:3901} INFO - 0 downstream tasks scheduled from follow-on schedule check
[2025-02-19T14:21:09.194+0000] {local_task_job_runner.py:245} INFO - ::endgroup::
